<?xml version="1.0" ?>
<!-- =================================================================================== -->
<!-- |    This document was autogenerated by xacro from /home/arjun/sim_ws/src/urdF_description/urdf/shobot.xacro | -->
<!-- |    EDITING THIS FILE BY HAND IS NOT RECOMMENDED                                 | -->
<!-- =================================================================================== -->
<robot name="shobot">
    <!--
    Base UR robot series xacro macro.

    NOTE: this is NOT a URDF. It cannot directly be loaded by consumers
    expecting a flattened '.urdf' file. See the top-level '.xacro' for that
    (but note: that .xacro must still be processed by the xacro command).

    For use in '.launch' files: use one of the 'load_urX.launch' convenience
    launch files.

    This file models the base kinematic chain of a UR robot, which then gets
    parameterised by various configuration files to convert it into a UR3(e),
    UR5(e), UR10(e) or UR16e.

    NOTE: the default kinematic parameters (ie: link lengths, frame locations,
    offets, etc) do not correspond to any particular robot. They are defaults
    only. There WILL be non-zero offsets between the Forward Kinematics results
    in TF (ie: robot_state_publisher) and the values reported by the Teach
    Pendant.

    For accurate (and robot-specific) transforms, the 'kinematics_parameters_file'
    parameter MUST point to a .yaml file containing the appropriate values for
    the targetted robot.

    If using the UniversalRobots/Universal_Robots_ROS_Driver, follow the steps
    described in the readme of that repository to extract the kinematic
    calibration from the controller and generate the required .yaml file.

    Main author of the migration to yaml configs: Ludovic Delval.

    Contributors to previous versions (in no particular order):

     - Felix Messmer
     - Kelsey Hawkins
     - Wim Meeussen
     - Shaun Edwards
     - Nadia Hammoudeh Garcia
     - Dave Hershberger
     - G. vd. Hoorn
     - Philip Long
     - Dave Coleman
     - Miguel Prada
     - Mathias Luedtke
     - Marcel Schnirring
     - Felix von Drigalski
     - Felix Exner
     - Jimmy Da Silva
     - Ajit Krisshna N L
     - Muhammad Asif Rana
  -->
    <!--
    NOTE: the macro defined in this file is NOT part of the public API of this
          package. Users CANNOT rely on this file being available, or stored in
          this location. Nor can they rely on the existence of the macro.
  -->
    <transmission name="shoulder_pan_trans">
        <type>transmission_interface/SimpleTransmission</type>
        <joint name="shoulder_pan_joint">
            <hardwareInterface>hardware_interface/EffortJointInterface</hardwareInterface>
        </joint>
        <actuator name="shoulder_pan_motor">
            <mechanicalReduction>1</mechanicalReduction>
            <hardwareInterface>hardware_interface/EffortJointInterface</hardwareInterface>
        </actuator>
    </transmission>
    <transmission name="shoulder_lift_trans">
        <type>transmission_interface/SimpleTransmission</type>
        <joint name="shoulder_lift_joint">
            <hardwareInterface>hardware_interface/EffortJointInterface</hardwareInterface>
        </joint>
        <actuator name="shoulder_lift_motor">
            <mechanicalReduction>1</mechanicalReduction>
            <hardwareInterface>hardware_interface/EffortJointInterface</hardwareInterface>
        </actuator>
    </transmission>
    <transmission name="elbow_trans">
        <type>transmission_interface/SimpleTransmission</type>
        <joint name="elbow_joint">
            <hardwareInterface>hardware_interface/EffortJointInterface</hardwareInterface>
        </joint>
        <actuator name="elbow_motor">
            <mechanicalReduction>1</mechanicalReduction>
            <hardwareInterface>hardware_interface/EffortJointInterface</hardwareInterface>
        </actuator>
    </transmission>
    <transmission name="wrist_1_trans">
        <type>transmission_interface/SimpleTransmission</type>
        <joint name="wrist_1_joint">
            <hardwareInterface>hardware_interface/EffortJointInterface</hardwareInterface>
        </joint>
        <actuator name="wrist_1_motor">
            <mechanicalReduction>1</mechanicalReduction>
            <hardwareInterface>hardware_interface/EffortJointInterface</hardwareInterface>
        </actuator>
    </transmission>
    <transmission name="wrist_2_trans">
        <type>transmission_interface/SimpleTransmission</type>
        <joint name="wrist_2_joint">
            <hardwareInterface>hardware_interface/EffortJointInterface</hardwareInterface>
        </joint>
        <actuator name="wrist_2_motor">
            <mechanicalReduction>1</mechanicalReduction>
            <hardwareInterface>hardware_interface/EffortJointInterface</hardwareInterface>
        </actuator>
    </transmission>
    <transmission name="wrist_3_trans">
        <type>transmission_interface/SimpleTransmission</type>
        <joint name="wrist_3_joint">
            <hardwareInterface>hardware_interface/EffortJointInterface</hardwareInterface>
        </joint>
        <actuator name="wrist_3_motor">
            <mechanicalReduction>1</mechanicalReduction>
            <hardwareInterface>hardware_interface/EffortJointInterface</hardwareInterface>
        </actuator>
    </transmission>
    <!-- links: main serial chain -->
    <link name="base_link" />
    <link name="base_link_inertia">
        <visual>
            <origin rpy="0 0 3.141592653589793" xyz="0 0 0" />
            <geometry>
                <mesh filename="package://ur_description/meshes/ur5/visual/base.dae" />
            </geometry>
            <material name="LightGrey">
                <color rgba="0.7 0.7 0.7 1.0" />
            </material>
        </visual>
        <collision>
            <origin rpy="0 0 3.141592653589793" xyz="0 0 0" />
            <geometry>
                <mesh filename="package://ur_description/meshes/ur5/collision/base.stl" />
            </geometry>
        </collision>
        <inertial>
            <mass value="4.0" />
            <origin rpy="0 0 0" xyz="0 0 0" />
            <inertia ixx="0.00443333156" ixy="0.0" ixz="0.0" iyy="0.00443333156" iyz="0.0" izz="0.0072" />
        </inertial>
    </link>
    <link name="shoulder_link">
        <visual>
            <origin rpy="0 0 3.141592653589793" xyz="0 0 0" />
            <geometry>
                <mesh filename="package://ur_description/meshes/ur5/visual/shoulder.dae" />
            </geometry>
            <material name="LightGrey">
                <color rgba="0.7 0.7 0.7 1.0" />
            </material>
        </visual>
        <collision>
            <origin rpy="0 0 3.141592653589793" xyz="0 0 0" />
            <geometry>
                <mesh filename="package://ur_description/meshes/ur5/collision/shoulder.stl" />
            </geometry>
        </collision>
        <inertial>
            <mass value="3.7" />
            <origin rpy="0 0 0" xyz="0 0 0" />
            <inertia ixx="0.014972352344389999" ixy="0.0" ixz="0.0" iyy="0.014972352344389999" iyz="0.0" izz="0.01040625" />
        </inertial>
    </link>
    <link name="upper_arm_link">
        <visual>
            <origin rpy="1.5707963267948966 0 -1.5707963267948966" xyz="0 0 0.13585" />
            <geometry>
                <mesh filename="package://ur_description/meshes/ur5/visual/upperarm.dae" />
            </geometry>
            <material name="LightGrey">
                <color rgba="0.7 0.7 0.7 1.0" />
            </material>
        </visual>
        <collision>
            <origin rpy="1.5707963267948966 0 -1.5707963267948966" xyz="0 0 0.13585" />
            <geometry>
                <mesh filename="package://ur_description/meshes/ur5/collision/upperarm.stl" />
            </geometry>
        </collision>
        <inertial>
            <mass value="8.393" />
            <origin rpy="0 1.5707963267948966 0" xyz="-0.2125 0.0 0.136" />
            <inertia ixx="0.1338857818623325" ixy="0.0" ixz="0.0" iyy="0.1338857818623325" iyz="0.0" izz="0.0151074" />
        </inertial>
    </link>
    <link name="forearm_link">
        <visual>
            <origin rpy="1.5707963267948966 0 -1.5707963267948966" xyz="0 0 0.0165" />
            <geometry>
                <mesh filename="package://ur_description/meshes/ur5/visual/forearm.dae" />
            </geometry>
            <material name="LightGrey">
                <color rgba="0.7 0.7 0.7 1.0" />
            </material>
        </visual>
        <collision>
            <origin rpy="1.5707963267948966 0 -1.5707963267948966" xyz="0 0 0.0165" />
            <geometry>
                <mesh filename="package://ur_description/meshes/ur5/collision/forearm.stl" />
            </geometry>
        </collision>
        <inertial>
            <mass value="2.275" />
            <origin rpy="0 1.5707963267948966 0" xyz="-0.196125 0.0 0.0165" />
            <inertia ixx="0.03121679102890359" ixy="0.0" ixz="0.0" iyy="0.03121679102890359" iyz="0.0" izz="0.004095" />
        </inertial>
    </link>
    <link name="wrist_1_link">
        <visual>
            <!-- TODO: Move this to a parameter -->
            <origin rpy="1.5707963267948966 0 0" xyz="0 0 -0.093" />
            <geometry>
                <mesh filename="package://ur_description/meshes/ur5/visual/wrist1.dae" />
            </geometry>
            <material name="LightGrey">
                <color rgba="0.7 0.7 0.7 1.0" />
            </material>
        </visual>
        <collision>
            <origin rpy="1.5707963267948966 0 0" xyz="0 0 -0.093" />
            <geometry>
                <mesh filename="package://ur_description/meshes/ur5/collision/wrist1.stl" />
            </geometry>
        </collision>
        <inertial>
            <mass value="1.219" />
            <origin rpy="0 0 0" xyz="0 0 0" />
            <inertia ixx="0.0020138887777775" ixy="0.0" ixz="0.0" iyy="0.0020138887777775" iyz="0.0" izz="0.0021942" />
        </inertial>
    </link>
    <link name="wrist_2_link">
        <visual>
            <origin rpy="0 0 0" xyz="0 0 -0.095" />
            <geometry>
                <mesh filename="package://ur_description/meshes/ur5/visual/wrist2.dae" />
            </geometry>
            <material name="LightGrey">
                <color rgba="0.7 0.7 0.7 1.0" />
            </material>
        </visual>
        <collision>
            <origin rpy="0 0 0" xyz="0 0 -0.095" />
            <geometry>
                <mesh filename="package://ur_description/meshes/ur5/collision/wrist2.stl" />
            </geometry>
        </collision>
        <inertial>
            <mass value="1.219" />
            <origin rpy="0 0 0" xyz="0 0 0" />
            <inertia ixx="0.0018310388509175" ixy="0.0" ixz="0.0" iyy="0.0018310388509175" iyz="0.0" izz="0.0021942" />
        </inertial>
    </link>
    <link name="wrist_3_link">
        <visual>
            <origin rpy="1.5707963267948966 0 0" xyz="0 0 -0.0818" />
            <geometry>
                <mesh filename="package://ur_description/meshes/ur5/visual/wrist3.dae" />
            </geometry>
            <material name="LightGrey">
                <color rgba="0.7 0.7 0.7 1.0" />
            </material>
        </visual>
        <collision>
            <origin rpy="1.5707963267948966 0 0" xyz="0 0 -0.0818" />
            <geometry>
                <mesh filename="package://ur_description/meshes/ur5/collision/wrist3.stl" />
            </geometry>
        </collision>
        <inertial>
            <mass value="0.1879" />
            <origin rpy="0 0 0" xyz="0.0 0.0 -0.01525" />
            <inertia ixx="8.062472608343e-05" ixy="0.0" ixz="0.0" iyy="8.062472608343e-05" iyz="0.0" izz="0.0001321171875" />
        </inertial>
    </link>
    <!-- joints: main serial chain -->
    <joint name="base_link-base_link_inertia" type="fixed">
        <parent link="base_link" />
        <child link="base_link_inertia" />
        <!-- 'base_link' is REP-103 aligned (so X+ forward), while the internal
           frames of the robot/controller have X+ pointing backwards.
           Use the joint between 'base_link' and 'base_link_inertia' (a dummy
           link/frame) to introduce the necessary rotation over Z (of pi rad).
      -->
        <origin rpy="0 0 3.141592653589793" xyz="0 0 0" />
    </joint>
    <joint name="shoulder_pan_joint" type="revolute">
        <parent link="base_link_inertia" />
        <child link="shoulder_link" />
        <origin rpy="0 0 0" xyz="0 0 0.089159" />
        <axis xyz="0 0 1" />
        <limit effort="150.0" lower="-6.283185307179586" upper="6.283185307179586" velocity="3.141592653589793" />
        <dynamics damping="0" friction="0" />
    </joint>
    <joint name="shoulder_lift_joint" type="revolute">
        <parent link="shoulder_link" />
        <child link="upper_arm_link" />
        <origin rpy="1.570796327 0 0" xyz="0 0 0" />
        <axis xyz="0 0 1" />
        <limit effort="150.0" lower="-6.283185307179586" upper="6.283185307179586" velocity="3.141592653589793" />
        <dynamics damping="0" friction="0" />
    </joint>
    <joint name="elbow_joint" type="revolute">
        <parent link="upper_arm_link" />
        <child link="forearm_link" />
        <origin rpy="0 0 0" xyz="-0.425 0 0" />
        <axis xyz="0 0 1" />
        <limit effort="150.0" lower="-3.141592653589793" upper="3.141592653589793" velocity="3.141592653589793" />
        <dynamics damping="0" friction="0" />
    </joint>
    <joint name="wrist_1_joint" type="revolute">
        <parent link="forearm_link" />
        <child link="wrist_1_link" />
        <origin rpy="0 0 0" xyz="-0.39225 0 0.10915" />
        <axis xyz="0 0 1" />
        <limit effort="28.0" lower="-6.283185307179586" upper="6.283185307179586" velocity="3.141592653589793" />
        <dynamics damping="0" friction="0" />
    </joint>
    <joint name="wrist_2_joint" type="revolute">
        <parent link="wrist_1_link" />
        <child link="wrist_2_link" />
        <origin rpy="1.570796327 0 0" xyz="0 -0.09465 -1.941303950897609e-11" />
        <axis xyz="0 0 1" />
        <limit effort="28.0" lower="-6.283185307179586" upper="6.283185307179586" velocity="3.141592653589793" />
        <dynamics damping="0" friction="0" />
    </joint>
    <joint name="wrist_3_joint" type="revolute">
        <parent link="wrist_2_link" />
        <child link="wrist_3_link" />
        <origin rpy="1.570796326589793 3.141592653589793 3.141592653589793" xyz="0 0.0823 -1.688001216681175e-11" />
        <axis xyz="0 0 1" />
        <limit effort="28.0" lower="-6.283185307179586" upper="6.283185307179586" velocity="3.141592653589793" />
        <dynamics damping="0" friction="0" />
    </joint>
    <!-- ROS-Industrial 'base' frame: base_link to UR 'Base' Coordinates transform -->
    <link name="base" />
    <joint name="base_link-base_fixed_joint" type="fixed">
        <!-- Note the rotation over Z of pi radians: as base_link is REP-103
           aligned (ie: has X+ forward, Y+ left and Z+ up), this is needed
           to correctly align 'base' with the 'Base' coordinate system of
           the UR controller.
      -->
        <origin rpy="0 0 3.141592653589793" xyz="0 0 0" />
        <parent link="base_link" />
        <child link="base" />
    </joint>
    <!-- ROS-Industrial 'flange' frame: attachment point for EEF models -->
    <link name="flange" />
    <joint name="wrist_3-flange" type="fixed">
        <parent link="wrist_3_link" />
        <child link="flange" />
        <origin rpy="0 -1.5707963267948966 -1.5707963267948966" xyz="0 0 0" />
    </joint>
    <!-- ROS-Industrial 'tool0' frame: all-zeros tool frame -->
    <link name="tool0" />
    <joint name="flange-tool0" type="fixed">
        <!-- default toolframe: X+ left, Y+ up, Z+ front -->
        <origin rpy="1.5707963267948966 0 1.5707963267948966" xyz="0 0 0" />
        <parent link="flange" />
        <child link="tool0" />
    </joint>
    <!-- Configure self collision properties per link -->
    <gazebo reference="shoulder_link">
        <selfCollide>true</selfCollide>
        <plugin name="gazebo_ros_control">
            <robotNamespace>/</robotNamespace>
        </plugin>
    </gazebo>
    <gazebo reference="upper_arm_link">
        <selfCollide>true</selfCollide>
    </gazebo>
    <gazebo reference="forearm_link">
        <selfCollide>true</selfCollide>
    </gazebo>
    <gazebo reference="wrist_1_link">
        <selfCollide>true</selfCollide>
    </gazebo>
    <gazebo reference="wrist_3_link">
        <selfCollide>true</selfCollide>
    </gazebo>
    <gazebo reference="wrist_2_link">
        <selfCollide>true</selfCollide>
    </gazebo>
    <gazebo reference="ee_link">
        <selfCollide>true</selfCollide>
    </gazebo>
    <material name="silver">
        <color rgba="0.700 0.700 0.700 1.000" />
    </material>
    <transmission name="Revolute_1_tran">
        <type>transmission_interface/SimpleTransmission</type>
        <joint name="Revolute_1">
            <hardwareInterface>hardware_interface/EffortJointInterface</hardwareInterface>
        </joint>
        <actuator name="Revolute_1_actr">
            <hardwareInterface>hardware_interface/EffortJointInterface</hardwareInterface>
            <mechanicalReduction>1</mechanicalReduction>
        </actuator>
    </transmission>
    <transmission name="Revolute_2_tran">
        <type>transmission_interface/SimpleTransmission</type>
        <joint name="Revolute_2">
            <hardwareInterface>hardware_interface/EffortJointInterface</hardwareInterface>
        </joint>
        <actuator name="Revolute_2_actr">
            <hardwareInterface>hardware_interface/EffortJointInterface</hardwareInterface>
            <mechanicalReduction>1</mechanicalReduction>
        </actuator>
    </transmission>
    <transmission name="Revolute_3_tran">
        <type>transmission_interface/SimpleTransmission</type>
        <joint name="Revolute_3">
            <hardwareInterface>hardware_interface/EffortJointInterface</hardwareInterface>
        </joint>
        <actuator name="Revolute_3_actr">
            <hardwareInterface>hardware_interface/EffortJointInterface</hardwareInterface>
            <mechanicalReduction>1</mechanicalReduction>
        </actuator>
    </transmission>
    <transmission name="Revolute_4_tran">
        <type>transmission_interface/SimpleTransmission</type>
        <joint name="Revolute_4">
            <hardwareInterface>hardware_interface/EffortJointInterface</hardwareInterface>
        </joint>
        <actuator name="Revolute_4_actr">
            <hardwareInterface>hardware_interface/EffortJointInterface</hardwareInterface>
            <mechanicalReduction>1</mechanicalReduction>
        </actuator>
    </transmission>
    <gazebo>
        <plugin filename="libgazebo_ros_control.so" name="control" />
    </gazebo>
    <gazebo reference="amr_link">
        <material>Gazebo/Silver</material>
        <mu1>0.2</mu1>
        <mu2>0.2</mu2>
        <selfCollide>true</selfCollide>
        <gravity>true</gravity>
    </gazebo>
    <gazebo reference="L_WHEEL_F_1">
        <material>Gazebo/Silver</material>
        <mu1>0.2</mu1>
        <mu2>0.2</mu2>
        <selfCollide>true</selfCollide>
    </gazebo>
    <gazebo reference="L_WHEEL_B_1">
        <material>Gazebo/Silver</material>
        <mu1>0.2</mu1>
        <mu2>0.2</mu2>
        <selfCollide>true</selfCollide>
    </gazebo>
    <gazebo reference="R_WHEEL_B_1">
        <material>Gazebo/Silver</material>
        <mu1>0.2</mu1>
        <mu2>0.2</mu2>
        <selfCollide>true</selfCollide>
    </gazebo>
    <gazebo reference="R_WHEEL_F_1">
        <material>Gazebo/Silver</material>
        <mu1>0.2</mu1>
        <mu2>0.2</mu2>
        <selfCollide>true</selfCollide>
    </gazebo>
    <gazebo reference="Top_Body_1">
        <material>Gazebo/Silver</material>
        <mu1>0.2</mu1>
        <mu2>0.2</mu2>
        <selfCollide>true</selfCollide>
    </gazebo>
    <material name="white">
        <color rgba="1.000 1.000 1.000 1.000" />
    </material>
    <gazebo>
        <plugin filename="libgazebo_ros_vacuum_gripper.so" name="gazebo_ros_vacuum_gripper">
            <robotNamespace>/urdF/vacuum_gripper</robotNamespace>
            <bodyName>vacuum_gripper</bodyName>
            <topicName>grasping</topicName>
            <maxForce>50</maxForce>
            <maxDistance>0.05</maxDistance>
            <minDistance>0.01</minDistance>
        </plugin>
    </gazebo>
    <gazebo>
        <plugin filename="libgazebo_ros_vacuum_gripper.so" name="gazebo_ros_vacuum_gripper1">
            <robotNamespace>/urdF/vacuum_gripper1</robotNamespace>
            <bodyName>vacuum_gripper1</bodyName>
            <topicName>grasping1</topicName>
            <maxForce>50</maxForce>
            <maxDistance>0.05</maxDistance>
            <minDistance>0.01</minDistance>
        </plugin>
    </gazebo>
    <gazebo>
        <plugin filename="libgazebo_ros_vacuum_gripper.so" name="gazebo_ros_vacuum_gripper2">
            <robotNamespace>/urdF/vacuum_gripper2</robotNamespace>
            <bodyName>vacuum_gripper2</bodyName>
            <topicName>grasping1</topicName>
            <maxForce>50</maxForce>
            <maxDistance>0.05</maxDistance>
            <minDistance>0.01</minDistance>
        </plugin>
    </gazebo>
    <gazebo>
        <plugin filename="libgazebo_ros_vacuum_gripper.so" name="gazebo_ros_vacuum_gripper3">
            <robotNamespace>/urdF/vacuum_gripper3</robotNamespace>
            <bodyName>vacuum_gripper3</bodyName>
            <topicName>grasping1</topicName>
            <maxForce>50</maxForce>
            <maxDistance>0.05</maxDistance>
            <minDistance>0.01</minDistance>
        </plugin>
    </gazebo>
    <gazebo>
        <plugin filename="libgazebo_ros_vacuum_gripper.so" name="gazebo_ros_vacuum_gripper4">
            <robotNamespace>/urdF/vacuum_gripper4</robotNamespace>
            <bodyName>vacuum_gripper4</bodyName>
            <topicName>grasping1</topicName>
            <maxForce>50</maxForce>
            <maxDistance>0.05</maxDistance>
            <minDistance>0.01</minDistance>
        </plugin>
    </gazebo>
    <gazebo>
        <plugin filename="libgazebo_ros_vacuum_gripper.so" name="gazebo_ros_vacuum_gripper5">
            <robotNamespace>/urdF/vacuum_gripper5</robotNamespace>
            <bodyName>vacuum_gripper5</bodyName>
            <topicName>grasping1</topicName>
            <maxForce>50</maxForce>
            <maxDistance>0.05</maxDistance>
            <minDistance>0.01</minDistance>
        </plugin>
    </gazebo>
    <gazebo>
        <plugin filename="libgazebo_ros_vacuum_gripper.so" name="gazebo_ros_vacuum_gripper6">
            <robotNamespace>/urdF/vacuum_gripper6</robotNamespace>
            <bodyName>vacuum_gripper6</bodyName>
            <topicName>grasping1</topicName>
            <maxForce>50</maxForce>
            <maxDistance>0.05</maxDistance>
            <minDistance>0.01</minDistance>
        </plugin>
    </gazebo>
    <gazebo>
        <plugin filename="libgazebo_ros_vacuum_gripper.so" name="gazebo_ros_vacuum_gripper7">
            <robotNamespace>/urdF/vacuum_gripper7</robotNamespace>
            <bodyName>vacuum_gripper7</bodyName>
            <topicName>grasping1</topicName>
            <maxForce>50</maxForce>
            <maxDistance>0.05</maxDistance>
            <minDistance>0.01</minDistance>
        </plugin>
    </gazebo>
    <link name="gripper_link">
        <inertial>
            <origin rpy="0 0 0" xyz="-0.0009694091187008012 -0.06077237045730904 0.06399399522278051" />
            <mass value="8.457717281604213" />
            <inertia ixx="0.047172" ixy="8e-05" ixz="-0.000141" iyy="0.016022" iyz="-9.3e-05" izz="0.047169" />
        </inertial>
        <visual>
            <origin rpy="0 0 0" xyz="0 0 0" />
            <geometry>
                <mesh filename="package://Vaccume_description/meshes/base_link.stl" scale="0.001 0.001 0.001" />
            </geometry>
            <material name="silver" />
        </visual>
        <collision>
            <origin rpy="0 0 0" xyz="0 0 0" />
            <geometry>
                <mesh filename="package://Vaccume_description/meshes/base_link.stl" scale="0.001 0.001 0.001" />
            </geometry>
        </collision>
    </link>
    <link name="vacuum_gripper">
        <gravity>0</gravity>
        <visual>
            <origin rpy="0 0 0" xyz="0 0 0" />
            <geometry>
                <cylinder length="0.01" radius="0.005" />
            </geometry>
            <material name="transparent">
                <color rgba="0 0 0 0" />
            </material>
        </visual>
        <collision>
            <origin rpy="0 0 0" xyz="0 0 0" />
            <geometry>
                <cylinder length="0.01" radius="0.005" />
            </geometry>
            <material name="transparent">
                <color rgba="0 0 0 0" />
            </material>
        </collision>
        <inertial>
            <origin rpy="0 0 0" xyz="0.000000 0.000000 0.000000" />
            <mass value="0.0001" />
            <inertia ixx="1e-08" ixy="0" ixz="0" iyy="1e-08" iyz="0" izz="1e-08" />
        </inertial>
    </link>
    <joint name="gripper_joint" type="revolute">
        <axis xyz="1 0 0" />
        <parent link="gripper_link" />
        <child link="vacuum_gripper" />
        <origin rpy="0 1.57 1.57" xyz="0 -0.347 0.047" />
        <limit effort="60" lower="0" upper="0" velocity="50" />
        <dynamics damping="0.0" friction="10" />
    </joint>
    <link name="vacuum_gripper1">
        <gravity>0</gravity>
        <visual>
            <origin rpy="0 0 0" xyz="0 0 0" />
            <geometry>
                <cylinder length="0.01" radius="0.005" />
            </geometry>
            <material name="transparent">
                <color rgba="0 0 0 0" />
            </material>
        </visual>
        <collision>
            <origin rpy="0 0 0" xyz="0 0 0" />
            <geometry>
                <cylinder length="0.01" radius="0.005" />
            </geometry>
            <material name="transparent">
                <color rgba="0 0 0 0" />
            </material>
        </collision>
        <inertial>
            <origin rpy="0 0 0" xyz="0.000000 0.000000 0.000000" />
            <mass value="0.0001" />
            <inertia ixx="1e-08" ixy="0" ixz="0" iyy="1e-08" iyz="0" izz="1e-08" />
        </inertial>
    </link>
    <joint name="gripper_joint1" type="revolute">
        <axis xyz="1 0 0" />
        <parent link="gripper_link" />
        <child link="vacuum_gripper1" />
        <origin rpy="0 1.57 1.57" xyz="0.0 -0.347 0.08" />
        <limit effort="60" lower="0" upper="0" velocity="50" />
        <dynamics damping="0.0" friction="10" />
    </joint>
    <link name="vacuum_gripper2">
        <gravity>0</gravity>
        <visual>
            <origin rpy="0 0 0" xyz="0 0 0" />
            <geometry>
                <cylinder length="0.01" radius="0.005" />
            </geometry>
            <material name="transparent">
                <color rgba="0 0 0 0" />
            </material>
        </visual>
        <collision>
            <origin rpy="0 0 0" xyz="0 0 0" />
            <geometry>
                <cylinder length="0.01" radius="0.005" />
            </geometry>
            <material name="transparent">
                <color rgba="0 0 0 0" />
            </material>
        </collision>
        <inertial>
            <origin rpy="0 0 0" xyz="0.000000 0.000000 0.000000" />
            <mass value="0.0001" />
            <inertia ixx="1e-08" ixy="0" ixz="0" iyy="1e-08" iyz="0" izz="1e-08" />
        </inertial>
    </link>
    <joint name="gripper_joint2" type="revolute">
        <axis xyz="1 0 0" />
        <parent link="gripper_link" />
        <child link="vacuum_gripper2" />
        <origin rpy="0 1.57 1.57" xyz="0.013 -0.347 0.052" />
        <limit effort="60" lower="0" upper="0" velocity="50" />
        <dynamics damping="0.0" friction="10" />
    </joint>
    <link name="vacuum_gripper3">
        <gravity>0</gravity>
        <visual>
            <origin rpy="0 0 0" xyz="0 0 0" />
            <geometry>
                <cylinder length="0.01" radius="0.005" />
            </geometry>
            <material name="transparent">
                <color rgba="0 0 0 0" />
            </material>
        </visual>
        <collision>
            <origin rpy="0 0 0" xyz="0 0 0" />
            <geometry>
                <cylinder length="0.01" radius="0.005" />
            </geometry>
            <material name="transparent">
                <color rgba="0 0 0 0" />
            </material>
        </collision>
        <inertial>
            <origin rpy="0 0 0" xyz="0.000000 0.000000 0.000000" />
            <mass value="0.0001" />
            <inertia ixx="1e-08" ixy="0" ixz="0" iyy="1e-08" iyz="0" izz="1e-08" />
        </inertial>
    </link>
    <joint name="gripper_joint3" type="revolute">
        <axis xyz="1 0 0" />
        <parent link="gripper_link" />
        <child link="vacuum_gripper3" />
        <origin rpy="0 1.57 1.57" xyz="-0.013 -0.347 0.075" />
        <limit effort="60" lower="0" upper="0" velocity="50" />
        <dynamics damping="0.0" friction="10" />
    </joint>
    <link name="vacuum_gripper4">
        <gravity>0</gravity>
        <visual>
            <origin rpy="0 0 0" xyz="0 0 0" />
            <geometry>
                <cylinder length="0.01" radius="0.005" />
            </geometry>
            <material name="transparent">
                <color rgba="0 0 0 0" />
            </material>
        </visual>
        <collision>
            <origin rpy="0 0 0" xyz="0 0 0" />
            <geometry>
                <cylinder length="0.01" radius="0.005" />
            </geometry>
            <material name="transparent">
                <color rgba="0 0 0 0" />
            </material>
        </collision>
        <inertial>
            <origin rpy="0 0 0" xyz="0.000000 0.000000 0.000000" />
            <mass value="0.0001" />
            <inertia ixx="1e-08" ixy="0" ixz="0" iyy="1e-08" iyz="0" izz="1e-08" />
        </inertial>
    </link>
    <joint name="gripper_joint4" type="revolute">
        <axis xyz="1 0 0" />
        <parent link="gripper_link" />
        <child link="vacuum_gripper4" />
        <origin rpy="0 1.57 1.57" xyz="0.005 -0.347 0.06" />
        <limit effort="60" lower="0" upper="0" velocity="50" />
        <dynamics damping="0.0" friction="10" />
    </joint>
    <link name="vacuum_gripper5">
        <gravity>0</gravity>
        <visual>
            <origin rpy="0 0 0" xyz="0 0 0" />
            <geometry>
                <cylinder length="0.01" radius="0.005" />
            </geometry>
            <material name="transparent">
                <color rgba="0 0 0 0" />
            </material>
        </visual>
        <collision>
            <origin rpy="0 0 0" xyz="0 0 0" />
            <geometry>
                <cylinder length="0.01" radius="0.005" />
            </geometry>
            <material name="transparent">
                <color rgba="0 0 0 0" />
            </material>
        </collision>
        <inertial>
            <origin rpy="0 0 0" xyz="0.000000 0.000000 0.000000" />
            <mass value="0.0001" />
            <inertia ixx="1e-08" ixy="0" ixz="0" iyy="1e-08" iyz="0" izz="1e-08" />
        </inertial>
    </link>
    <joint name="gripper_joint5" type="revolute">
        <axis xyz="1 0 0" />
        <parent link="gripper_link" />
        <child link="vacuum_gripper5" />
        <origin rpy="0 1.57 1.57" xyz="-0.005 -0.347 0.06" />
        <limit effort="60" lower="0" upper="0" velocity="50" />
        <dynamics damping="0.0" friction="10" />
    </joint>
    <link name="vacuum_gripper6">
        <gravity>0</gravity>
        <visual>
            <origin rpy="0 0 0" xyz="0 0 0" />
            <geometry>
                <cylinder length="0.01" radius="0.005" />
            </geometry>
            <material name="transparent">
                <color rgba="0 0 0 0" />
            </material>
        </visual>
        <collision>
            <origin rpy="0 0 0" xyz="0 0 0" />
            <geometry>
                <cylinder length="0.01" radius="0.005" />
            </geometry>
            <material name="transparent">
                <color rgba="0 0 0 0" />
            </material>
        </collision>
        <inertial>
            <origin rpy="0 0 0" xyz="0.000000 0.000000 0.000000" />
            <mass value="0.0001" />
            <inertia ixx="1e-08" ixy="0" ixz="0" iyy="1e-08" iyz="0" izz="1e-08" />
        </inertial>
    </link>
    <joint name="gripper_joint6" type="revolute">
        <axis xyz="1 0 0" />
        <parent link="gripper_link" />
        <child link="vacuum_gripper6" />
        <origin rpy="0 1.57 1.57" xyz="0.007 -0.347 0.07" />
        <limit effort="60" lower="0" upper="0" velocity="50" />
        <dynamics damping="0.0" friction="10" />
    </joint>
    <link name="vacuum_gripper7">
        <gravity>0</gravity>
        <visual>
            <origin rpy="0 0 0" xyz="0 0 0" />
            <geometry>
                <cylinder length="0.01" radius="0.005" />
            </geometry>
            <material name="transparent">
                <color rgba="0 0 0 0" />
            </material>
        </visual>
        <collision>
            <origin rpy="0 0 0" xyz="0 0 0" />
            <geometry>
                <cylinder length="0.01" radius="0.005" />
            </geometry>
            <material name="transparent">
                <color rgba="0 0 0 0" />
            </material>
        </collision>
        <inertial>
            <origin rpy="0 0 0" xyz="0.000000 0.000000 0.000000" />
            <mass value="0.0001" />
            <inertia ixx="1e-08" ixy="0" ixz="0" iyy="1e-08" iyz="0" izz="1e-08" />
        </inertial>
    </link>
    <joint name="gripper_joint7" type="revolute">
        <axis xyz="1 0 0" />
        <parent link="gripper_link" />
        <child link="vacuum_gripper7" />
        <origin rpy="0 1.57 1.57" xyz="-0.007 -0.347 0.07" />
        <limit effort="60" lower="0" upper="0" velocity="50" />
        <dynamics damping="0.0" friction="10" />
    </joint>
    <link name="amr_link">
        <inertial>
            <origin rpy="0 0 0" xyz="7.980285628189428e-17 -3.990142814094714e-17 0.12803630068802982" />
            <mass value="916.117862361551" />
            <inertia ixx="29.080883" ixy="-0.0" ixz="0.0" iyy="62.895145" iyz="0.0" izz="82.576037" />
        </inertial>
        <visual>
            <origin rpy="0 0 0" xyz="0 0 0" />
            <geometry>
                <mesh filename="package://urdF_description/meshes/base_link.stl" scale="0.001 0.001 0.001" />
            </geometry>
            <material name="silver" />
        </visual>
        <collision>
            <origin rpy="0 0 0" xyz="0 0 0" />
            <geometry>
                <mesh filename="package://urdF_description/meshes/base_link.stl" scale="0.001 0.001 0.001" />
            </geometry>
        </collision>
    </link>
    <link name="L_WHEEL_F_1">
        <inertial>
            <origin rpy="0 0 0" xyz="1.27675647831893e-14 0.0 4.85722573273506e-17" />
            <mass value="5.05336007222817" />
            <inertia ixx="0.010871" ixy="0.0" ixz="0.0" iyy="0.021215" iyz="0.0" izz="0.010871" />
        </inertial>
        <visual>
            <origin rpy="0 0 0" xyz="-0.2125 -0.1325 -0.05" />
            <geometry>
                <mesh filename="package://urdF_description/meshes/L_WHEEL_F_1.stl" scale="0.001 0.001 0.001" />
            </geometry>
            <material name="silver" />
        </visual>
        <collision>
            <origin rpy="0 0 0" xyz="-0.2125 -0.1325 -0.05" />
            <geometry>
                <mesh filename="package://urdF_description/meshes/L_WHEEL_F_1.stl" scale="0.001 0.001 0.001" />
            </geometry>
        </collision>
    </link>
    <link name="L_WHEEL_B_1">
        <inertial>
            <origin rpy="0 0 0" xyz="1.2878587085651816e-14 0.0 1.1102230246251565e-16" />
            <mass value="5.05336007222817" />
            <inertia ixx="0.010871" ixy="-0.0" ixz="0.0" iyy="0.021215" iyz="0.0" izz="0.010871" />
        </inertial>
        <visual>
            <origin rpy="0 0 0" xyz="0.2125 -0.1325 -0.05" />
            <geometry>
                <mesh filename="package://urdF_description/meshes/L_WHEEL_B_1.stl" scale="0.001 0.001 0.001" />
            </geometry>
            <material name="silver" />
        </visual>
        <collision>
            <origin rpy="0 0 0" xyz="0.2125 -0.1325 -0.05" />
            <geometry>
                <mesh filename="package://urdF_description/meshes/L_WHEEL_B_1.stl" scale="0.001 0.001 0.001" />
            </geometry>
        </collision>
    </link>
    <link name="R_WHEEL_B_1">
        <inertial>
            <origin rpy="0 0 0" xyz="1.2823075934420558e-14 0.0 4.85722573273506e-17" />
            <mass value="5.05336007222817" />
            <inertia ixx="0.010871" ixy="0.0" ixz="0.0" iyy="0.021215" iyz="0.0" izz="0.010871" />
        </inertial>
        <visual>
            <origin rpy="0 0 0" xyz="0.2125 0.1325 -0.05" />
            <geometry>
                <mesh filename="package://urdF_description/meshes/R_WHEEL_B_1.stl" scale="0.001 0.001 0.001" />
            </geometry>
            <material name="silver" />
        </visual>
        <collision>
            <origin rpy="0 0 0" xyz="0.2125 0.1325 -0.05" />
            <geometry>
                <mesh filename="package://urdF_description/meshes/R_WHEEL_B_1.stl" scale="0.001 0.001 0.001" />
            </geometry>
        </collision>
    </link>
    <link name="R_WHEEL_F_1">
        <inertial>
            <origin rpy="0 0 0" xyz="0.0 0.0 1.2760625889285393e-14" />
            <mass value="5.05336007222817" />
            <inertia ixx="0.010871" ixy="0.0" ixz="0.0" iyy="0.021215" iyz="0.0" izz="0.010871" />
        </inertial>
        <visual>
            <origin rpy="0 0 0" xyz="-0.2125 0.1325 -0.05" />
            <geometry>
                <mesh filename="package://urdF_description/meshes/R_WHEEL_F_1.stl" scale="0.001 0.001 0.001" />
            </geometry>
            <material name="silver" />
        </visual>
        <collision>
            <origin rpy="0 0 0" xyz="-0.2125 0.1325 -0.05" />
            <geometry>
                <mesh filename="package://urdF_description/meshes/R_WHEEL_F_1.stl" scale="0.001 0.001 0.001" />
            </geometry>
        </collision>
    </link>
    <link name="Top_Body_1">
        <inertial>
            <origin rpy="0 0 0" xyz="-0.04261578492205568 -1.7700002588756798e-05 0.6563727706924719" />
            <mass value="363.27166737535043" />
            <inertia ixx="64.249865" ixy="0.001518" ixz="1.62817" iyy="62.201154" iyz="0.002613" izz="16.245371" />
        </inertial>
        <visual>
            <origin rpy="0 0 0" xyz="-0.0 0.0 -0.25" />
            <geometry>
                <mesh filename="package://urdF_description/meshes/Top_Body_1.stl" scale="0.001 0.001 0.001" />
            </geometry>
            <material name="silver" />
        </visual>
        <collision>
            <origin rpy="0 0 0" xyz="-0.0 0.0 -0.25" />
            <geometry>
                <mesh filename="package://urdF_description/meshes/Top_Body_1.stl" scale="0.001 0.001 0.001" />
            </geometry>
        </collision>
    </link>
    <joint name="Revolute_1" type="revolute">
        <origin rpy="0 0 0" xyz="0.2125 0.1325 0.05" />
        <parent link="amr_link" />
        <child link="L_WHEEL_F_1" />
        <axis xyz="0.0 1.0 0.0" />
        <limit effort="10" lower="-3.14159" upper="3.14159" velocity="1" />
        <dynamics damping="0" friction="0" />
    </joint>
    <joint name="Revolute_2" type="revolute">
        <origin rpy="0 0 0" xyz="-0.2125 0.1325 0.05" />
        <parent link="amr_link" />
        <child link="L_WHEEL_B_1" />
        <axis xyz="0.0 1.0 0.0" />
        <limit effort="10" lower="-3.14159" upper="3.14159" velocity="1" />
        <dynamics damping="0" friction="0" />
    </joint>
    <joint name="Revolute_3" type="revolute">
        <origin rpy="0 0 0" xyz="-0.2125 -0.1325 0.05" />
        <parent link="amr_link" />
        <child link="R_WHEEL_B_1" />
        <axis xyz="0.0 1.0 0.0" />
        <limit effort="10" lower="-3.14159" upper="3.14159" velocity="1" />
        <dynamics damping="0" friction="0" />
    </joint>
    <joint name="Revolute_4" type="revolute">
        <origin rpy="0 0 0" xyz="0.2125 -0.1325 0.05" />
        <parent link="amr_link" />
        <child link="R_WHEEL_F_1" />
        <axis xyz="0.0 1.0 0.0" />
        <limit effort="10" lower="-3.14159" upper="3.14159" velocity="1" />
        <dynamics damping="0" friction="0" />
    </joint>
    <joint name="Rigid_6" type="fixed">
        <origin rpy="0 0 0" xyz="0.0 0.0 0.25" />
        <parent link="amr_link" />
        <child link="Top_Body_1" />
    </joint>
    <joint name="UR5_joint" type="fixed">
        <origin rpy="0 -1.57 0" xyz="-0.21 0.0 0.84" />
        <parent link="Top_Body_1" />
        <child link="base_link" />
    </joint>
    <link name="world" />
    <joint name="world_to_amr" type="fixed">
        <parent link="world" />
        <child link="amr_link" />
        <origin rpy="0 0 0" xyz="0 0 0" />
    </joint>
    <joint name="coupler_joint" type="fixed">
        <parent link="tool0" />
        <child link="gripper_link" />
        <origin rpy="-1.57 0 -0.78" xyz="-0.045 -0.045 0.01" />
    </joint>
    <!-- xacro:include filename="$(find common_sensors)/urdf/sensors/kinect_properties.urdf.xacro"/ -->
    <gazebo reference="camera_depth_frame">
        <sensor name="camera1" type="depth">
            <always_on>true</always_on>
            <update_rate>20.0</update_rate>
            <camera>
                <horizontal_fov>1.0471975511965976</horizontal_fov>
                <image>
                    <format>R8G8B8</format>
                    <width>640</width>
                    <height>480</height>
                </image>
                <clip>
                    <near>0.05</near>
                    <far>8.0</far>
                </clip>
            </camera>
            <plugin filename="libgazebo_ros_openni_kinect.so" name="camera_depth_frame_kinect_controller">
                <baseline>0.1</baseline>
                <alwaysOn>true</alwaysOn>
                <updateRate>10</updateRate>
                <cameraName>camera1</cameraName>
                <imageTopicName>rgb/image_raw</imageTopicName>
                <cameraInfoTopicName>rgb/camera_info</cameraInfoTopicName>
                <depthImageTopicName>depth/image_raw</depthImageTopicName>
                <depthImageCameraInfoTopicName>depth/camera_info</depthImageCameraInfoTopicName>
                <pointCloudTopicName>depth/points</pointCloudTopicName>
                <frameName>camera_depth_optical_frame</frameName>
                <pointCloudCutoff>0.3</pointCloudCutoff>
                <distortion_k1>0.0</distortion_k1>
                <distortion_k2>0.0</distortion_k2>
                <distortion_k3>0.0</distortion_k3>
                <distortion_t1>0.0</distortion_t1>
                <distortion_t2>0.0</distortion_t2>
                <!--
          <CxPrime>0</CxPrime>
          <Cx>0</Cx>
          <Cy>0</Cy>
          <focalLength>0</focalLength>
          <hackBaseline>0</hackBaseline>
      -->
            </plugin>
        </sensor>
    </gazebo>
    <joint name="camera_rgb_joint" type="fixed">
        <origin rpy="0 0.175 1.57" xyz="-0.09 0.29 1.4" />
        <parent link="world" />
        <child link="camera_rgb_frame" />
    </joint>
    <link name="camera_rgb_frame">
        <inertial>
            <mass value="0.001" />
            <origin xyz="0 0 0" />
            <inertia ixx="0.0001" ixy="0.0" ixz="0.0" iyy="0.0001" iyz="0.0" izz="0.0001" />
        </inertial>
    </link>
    <joint name="camera_rgb_optical_joint" type="fixed">
        <origin rpy="-1.5707963267948966 0 -1.5707963267948966" xyz="0 0 0" />
        <parent link="camera_rgb_frame" />
        <child link="camera_rgb_optical_frame" />
    </joint>
    <link name="camera_rgb_optical_frame">
        <inertial>
            <mass value="0.001" />
            <origin xyz="0 0 0" />
            <inertia ixx="0.0001" ixy="0.0" ixz="0.0" iyy="0.0001" iyz="0.0" izz="0.0001" />
        </inertial>
    </link>
    <joint name="camera_joint" type="fixed">
        <origin rpy="0 0 0" xyz="-0.031 0.0 -0.016" />
        <parent link="camera_rgb_frame" />
        <child link="camera_link" />
    </joint>
    <link name="camera_link">
        <visual>
            <origin rpy="0 0 1.5707963267948966" xyz="0 0 0" />
            <geometry>
                <mesh filename="package://common_sensors/meshes/sensors/kinect.dae" />
            </geometry>
        </visual>
        <collision>
            <origin rpy="0 0 0" xyz="0.0 0.0 0.0" />
            <geometry>
                <box size="0.07271 0.27794 0.073" />
            </geometry>
        </collision>
        <inertial>
            <mass value="0.001" />
            <origin xyz="0 0 0" rpy="0 0 0" />
            <inertia ixx="0.0001" ixy="0.0" ixz="0.0" iyy="0.0001" iyz="0.0" izz="0.0001" />
        </inertial>
    </link>
    <!-- The fixed joints & links below are usually published by static_transformers launched by the OpenNi launch 
		 files. However, for Gazebo simulation we need them, so we add them here.
		 (Hence, don't publish them additionally!) -->
    <joint name="camera_depth_joint" type="fixed">
        <origin rpy="0 0 0" xyz="0 0 0" />
        <parent link="camera_rgb_frame" />
        <child link="camera_depth_frame" />
    </joint>
    <link name="camera_depth_frame">
        <inertial>
            <mass value="0.001" />
            <origin xyz="0 0 0" />
            <inertia ixx="0.0001" ixy="0.0" ixz="0.0" iyy="0.0001" iyz="0.0" izz="0.0001" />
        </inertial>
    </link>
    <joint name="camera_depth_optical_joint" type="fixed">
        <origin rpy="-1.5707963267948966 0 -1.5707963267948966" xyz="0 0 0" />
        <parent link="camera_depth_frame" />
        <child link="camera_depth_optical_frame" />
    </joint>
    <link name="camera_depth_optical_frame">
        <inertial>
            <mass value="0.001" />
            <origin xyz="0 0 0" />
            <inertia ixx="0.0001" ixy="0.0" ixz="0.0" iyy="0.0001" iyz="0.0" izz="0.0001" />
        </inertial>
    </link>
    <transmission name="trans_gripper_joint">
        <type>transmission_interface/SimpleTransmission</type>
        <joint name="gripper_joint">
            <hardwareInterface>hardware_interface/EffortJointInterface</hardwareInterface>
        </joint>
        <actuator name="gripper_joint_motor">
            <hardwareInterface>hardware_interface/EffortJointInterface</hardwareInterface>
            <mechanicalReduction>1</mechanicalReduction>
        </actuator>
    </transmission>
    <transmission name="trans_gripper_joint1">
        <type>transmission_interface/SimpleTransmission</type>
        <joint name="gripper_joint1">
            <hardwareInterface>hardware_interface/EffortJointInterface</hardwareInterface>
        </joint>
        <actuator name="gripper_joint1_motor">
            <hardwareInterface>hardware_interface/EffortJointInterface</hardwareInterface>
            <mechanicalReduction>1</mechanicalReduction>
        </actuator>
    </transmission>
    <transmission name="trans_gripper_joint2">
        <type>transmission_interface/SimpleTransmission</type>
        <joint name="gripper_joint2">
            <hardwareInterface>hardware_interface/EffortJointInterface</hardwareInterface>
        </joint>
        <actuator name="gripper_joint2_motor">
            <hardwareInterface>hardware_interface/EffortJointInterface</hardwareInterface>
            <mechanicalReduction>1</mechanicalReduction>
        </actuator>
    </transmission>
    <transmission name="trans_gripper_joint3">
        <type>transmission_interface/SimpleTransmission</type>
        <joint name="gripper_joint3">
            <hardwareInterface>hardware_interface/EffortJointInterface</hardwareInterface>
        </joint>
        <actuator name="gripper_joint3_motor">
            <hardwareInterface>hardware_interface/EffortJointInterface</hardwareInterface>
            <mechanicalReduction>1</mechanicalReduction>
        </actuator>
    </transmission>
    <transmission name="trans_gripper_joint4">
        <type>transmission_interface/SimpleTransmission</type>
        <joint name="gripper_joint4">
            <hardwareInterface>hardware_interface/EffortJointInterface</hardwareInterface>
        </joint>
        <actuator name="gripper_joint4_motor">
            <hardwareInterface>hardware_interface/EffortJointInterface</hardwareInterface>
            <mechanicalReduction>1</mechanicalReduction>
        </actuator>
    </transmission>
    <transmission name="trans_gripper_joint5">
        <type>transmission_interface/SimpleTransmission</type>
        <joint name="gripper_joint5">
            <hardwareInterface>hardware_interface/EffortJointInterface</hardwareInterface>
        </joint>
        <actuator name="gripper_joint5_motor">
            <hardwareInterface>hardware_interface/EffortJointInterface</hardwareInterface>
            <mechanicalReduction>1</mechanicalReduction>
        </actuator>
    </transmission>
    <transmission name="trans_gripper_joint6">
        <type>transmission_interface/SimpleTransmission</type>
        <joint name="gripper_joint6">
            <hardwareInterface>hardware_interface/EffortJointInterface</hardwareInterface>
        </joint>
        <actuator name="gripper_joint6_motor">
            <hardwareInterface>hardware_interface/EffortJointInterface</hardwareInterface>
            <mechanicalReduction>1</mechanicalReduction>
        </actuator>
    </transmission>
    <transmission name="trans_gripper_joint7">
        <type>transmission_interface/SimpleTransmission</type>
        <joint name="gripper_joint7">
            <hardwareInterface>hardware_interface/EffortJointInterface</hardwareInterface>
        </joint>
        <actuator name="gripper_joint7_motor">
            <hardwareInterface>hardware_interface/EffortJointInterface</hardwareInterface>
            <mechanicalReduction>1</mechanicalReduction>
        </actuator>
    </transmission>
</robot>

