<?xml version="1.0" ?>
<robot name="shobot" xmlns:xacro="http://www.ros.org/wiki/xacro">

  <xacro:include filename="$(find ur_description)/urdf/ur5.xacro" />
  <xacro:include filename="$(find urdF_description)/urdf/materials.xacro" />
  <xacro:include filename="$(find urdF_description)/urdf/urdF.trans" />
  <xacro:include filename="$(find urdF_description)/urdf/urdF.gazebo" />
  <xacro:include filename="$(find Vaccume_description)/urdf/Vaccume.xacro" />
  
  <link name="amr_link">
    <inertial>
      <origin xyz="7.980285628189428e-17 -3.990142814094714e-17 0.12803630068802982" rpy="0 0 0"/>
      <mass value="916.117862361551"/>
      <inertia ixx="29.080883" iyy="62.895145" izz="82.576037" ixy="-0.0" iyz="0.0" ixz="0.0"/>
    </inertial>
    <visual>
      <origin xyz="0 0 0" rpy="0 0 0"/>
      <geometry>
        <mesh filename="package://urdF_description/meshes/base_link.stl" scale="0.001 0.001 0.001"/>
      </geometry>
      <material name="silver"/>
    </visual>
    <collision>
      <origin xyz="0 0 0" rpy="0 0 0"/>
      <geometry>
        <mesh filename="package://urdF_description/meshes/base_link.stl" scale="0.001 0.001 0.001"/>
      </geometry>
    </collision>
  </link>

  <link name="L_WHEEL_F_1">
    <inertial>
      <origin xyz="1.27675647831893e-14 0.0 4.85722573273506e-17" rpy="0 0 0"/>
      <mass value="5.05336007222817"/>
      <inertia ixx="0.010871" iyy="0.021215" izz="0.010871" ixy="0.0" iyz="0.0" ixz="0.0"/>
    </inertial>
    <visual>
      <origin xyz="-0.2125 -0.1325 -0.05" rpy="0 0 0"/>
      <geometry>
        <mesh filename="package://urdF_description/meshes/L_WHEEL_F_1.stl" scale="0.001 0.001 0.001"/>
      </geometry>
      <material name="silver"/>
    </visual>
    <collision>
      <origin xyz="-0.2125 -0.1325 -0.05" rpy="0 0 0"/>
      <geometry>
        <mesh filename="package://urdF_description/meshes/L_WHEEL_F_1.stl" scale="0.001 0.001 0.001"/>
      </geometry>
    </collision>
  </link>

  <link name="L_WHEEL_B_1">
    <inertial>
      <origin xyz="1.2878587085651816e-14 0.0 1.1102230246251565e-16" rpy="0 0 0"/>
      <mass value="5.05336007222817"/>
      <inertia ixx="0.010871" iyy="0.021215" izz="0.010871" ixy="-0.0" iyz="0.0" ixz="0.0"/>
    </inertial>
    <visual>
      <origin xyz="0.2125 -0.1325 -0.05" rpy="0 0 0"/>
      <geometry>
        <mesh filename="package://urdF_description/meshes/L_WHEEL_B_1.stl" scale="0.001 0.001 0.001"/>
      </geometry>
      <material name="silver"/>
    </visual>
    <collision>
      <origin xyz="0.2125 -0.1325 -0.05" rpy="0 0 0"/>
      <geometry>
        <mesh filename="package://urdF_description/meshes/L_WHEEL_B_1.stl" scale="0.001 0.001 0.001"/>
      </geometry>
    </collision>
  </link>

  <link name="R_WHEEL_B_1">
    <inertial>
      <origin xyz="1.2823075934420558e-14 0.0 4.85722573273506e-17" rpy="0 0 0"/>
      <mass value="5.05336007222817"/>
      <inertia ixx="0.010871" iyy="0.021215" izz="0.010871" ixy="0.0" iyz="0.0" ixz="0.0"/>
    </inertial>
    <visual>
      <origin xyz="0.2125 0.1325 -0.05" rpy="0 0 0"/>
      <geometry>
        <mesh filename="package://urdF_description/meshes/R_WHEEL_B_1.stl" scale="0.001 0.001 0.001"/>
      </geometry>
      <material name="silver"/>
    </visual>
    <collision>
      <origin xyz="0.2125 0.1325 -0.05" rpy="0 0 0"/>
      <geometry>
        <mesh filename="package://urdF_description/meshes/R_WHEEL_B_1.stl" scale="0.001 0.001 0.001"/>
      </geometry>
    </collision>
  </link>

  <link name="R_WHEEL_F_1">
    <inertial>
      <origin xyz="0.0 0.0 1.2760625889285393e-14" rpy="0 0 0"/>
      <mass value="5.05336007222817"/>
      <inertia ixx="0.010871" iyy="0.021215" izz="0.010871" ixy="0.0" iyz="0.0" ixz="0.0"/>
    </inertial>
    <visual>
      <origin xyz="-0.2125 0.1325 -0.05" rpy="0 0 0"/>
      <geometry>
        <mesh filename="package://urdF_description/meshes/R_WHEEL_F_1.stl" scale="0.001 0.001 0.001"/>
      </geometry>
      <material name="silver"/>
    </visual>
    <collision>
      <origin xyz="-0.2125 0.1325 -0.05" rpy="0 0 0"/>
      <geometry>
        <mesh filename="package://urdF_description/meshes/R_WHEEL_F_1.stl" scale="0.001 0.001 0.001"/>
      </geometry>
    </collision>
  </link>

  <link name="Top_Body_1">
    <inertial>
      <origin xyz="-0.04261578492205568 -1.7700002588756798e-05 0.6563727706924719" rpy="0 0 0"/>
      <mass value="363.27166737535043"/>
      <inertia ixx="64.249865" iyy="62.201154" izz="16.245371" ixy="0.001518" iyz="0.002613" ixz="1.62817"/>
    </inertial>
    <visual>
      <origin xyz="-0.0 0.0 -0.25" rpy="0 0 0"/>
      <geometry>
        <mesh filename="package://urdF_description/meshes/Top_Body_1.stl" scale="0.001 0.001 0.001"/>
      </geometry>
      <material name="silver"/>
    </visual>
    <collision>
      <origin xyz="-0.0 0.0 -0.25" rpy="0 0 0"/>
      <geometry>
        <mesh filename="package://urdF_description/meshes/Top_Body_1.stl" scale="0.001 0.001 0.001"/>
      </geometry>
    </collision>
  </link>

  <joint name="Revolute_1" type="revolute">
    <origin xyz="0.2125 0.1325 0.05" rpy="0 0 0"/>
    <parent link="amr_link"/>
    <child link="L_WHEEL_F_1"/>
    <axis xyz="0.0 1.0 0.0"/>
    <limit lower = "-3.14159" upper = "3.14159" effort = "10" velocity = "1"/>
    <dynamics damping="0" friction="0"/>
  </joint>

  <joint name="Revolute_2" type="revolute">
    <origin xyz="-0.2125 0.1325 0.05" rpy="0 0 0"/>
    <parent link="amr_link"/>
    <child link="L_WHEEL_B_1"/>
    <axis xyz="0.0 1.0 0.0"/>
    <limit lower = "-3.14159" upper = "3.14159" effort = "10" velocity = "1"/>
    <dynamics damping="0" friction="0"/>
  </joint>

  <joint name="Revolute_3" type="revolute">
    <origin xyz="-0.2125 -0.1325 0.05" rpy="0 0 0"/>
    <parent link="amr_link"/>
    <child link="R_WHEEL_B_1"/>
    <axis xyz="0.0 1.0 0.0"/>
    <limit lower = "-3.14159" upper = "3.14159" effort = "10" velocity = "1"/>
    <dynamics damping="0" friction="0"/>
  </joint>

  <joint name="Revolute_4" type="revolute">
    <origin xyz="0.2125 -0.1325 0.05" rpy="0 0 0"/>
    <parent link="amr_link"/>
    <child link="R_WHEEL_F_1"/>
    <axis xyz="0.0 1.0 0.0"/>
    <limit lower = "-3.14159" upper = "3.14159" effort = "10" velocity = "1"/>
    <dynamics damping="0" friction="0"/>
  </joint>

  <joint name="Rigid_6" type="fixed">
    <origin xyz="0.0 0.0 0.25" rpy="0 0 0"/>
    <parent link="amr_link"/>
    <child link="Top_Body_1"/>
  </joint>

  <joint name="UR5_joint" type="fixed">
    <origin xyz="-0.21 0.0 0.84" rpy="0 -1.57 0"/>
    <parent link="Top_Body_1"/>
    <child link="base_link"/>
  </joint>

  <link name="world"/>

  <joint name="world_to_amr" type="fixed">
    <parent link="world"/>
    <child link="amr_link"/>
    <origin xyz="0 0 0" rpy="0 0 0"/>
  </joint>

  <joint name="coupler_joint" type="fixed">
    <parent link="tool0" />
    <child link="gripper_link" />
    <origin rpy="-1.57 0 -0.78" xyz="-0.045 -0.045 0.01" />
  </joint>

  <!--Kinect-->
  <!-- position of kinect has to be changed in common_sensors/urdf/sensors/kinect_properties.urdf.xacro--> 
  <xacro:include filename="$(find common_sensors)/urdf/sensors/kinect.urdf.xacro" />
  <xacro:sensor_kinect parent="world"/>

</robot>
